<mujoco model="uneven_terrain_scene_mjx">
  <compiler angle="radian" coordinate="local" meshdir="./stls/dual_ur5_husky" texturedir="./textures"/>

  <!--
  These options are crucial for stable simulation of contact-rich systems like wheeled robots.
  - solver="Newton" is more robust and accurate for complex contacts.
  - cone="elliptic" provides a more realistic friction model than the default.
  - timestep="0.002" is a standard for many robotics simulations.
  -->
<!--   <option timestep="0.002"
          iterations="10"
          tolerance="1e-10"
          impratio="10"
          gravity="0 0 -9.81"
          solver="Newton"
          cone="elliptic"/> -->

  <size nuserdata="100" njmax="500" nconmax="1000" nstack="600000" nuser_body="9" nuser_jnt="1" nuser_site="1" nuser_tendon="1" nuser_actuator="12" nuser_sensor="1"/>

  <visual>
    <headlight diffuse="0.6 0.6 0.6" ambient="0.3 0.3 0.3" specular="0 0 0"/>
    <rgba haze="0.15 0.25 0.35 1"/>
    <global offwidth="2048" offheight="1536" azimuth="-120" elevation="-20"/>
    <map fogstart="3" fogend="5" force="0.1" znear="0.1"/>
    <quality shadowsize="8192"/>
  </visual>

  <default>
    <!--
    Set condim="3" for standard anisotropic friction, which is good for wheels.
    Adjusted solimp and solref for more stable contacts.
    -->
    <geom contype="1" conaffinity="1" margin="0.001" solimp="0.9 0.95 0.001" solref="0.02 1" condim="3" friction="1.2 0.05 0.05"/>
    <joint armature="0.01" damping="0.1"/>
    <default class="UR5">
      <joint damping="200"/>
    </default>
    <default class="UR5e">
      <joint damping="100"/>
    </default>
    <default class="GRIPPER">
      <joint damping="5"/>
      <geom rgba="0.424 0.424 0.424 1.0" contype="1" conaffinity="1" type="mesh"/>
    </default>
    <default class="ur5:blue">
      <geom rgba="0.635 0.784 0.910 1.0"/>
    </default>
    <default class="ur5:grey">
      <geom rgba="0.365 0.365 0.365 1.0"/>
    </default>
    <default class="ur5:black">
      <geom rgba="0.106 0.106 0.106 1.0"/>
    </default>
    <default class="husky:orange">
      <geom rgba="0.996 0.941 0.412 1.0"/>
    </default>
    <default class="husky:black">
      <geom rgba="0.192 0.192 0.192 1.0"/>
    </default>
    <default class="gripper:black">
      <geom rgba="0.424 0.424 0.424 1.0"/>
    </default>
    <default class="gripper:white">
      <geom rgba="0.898 0.898 0.898 1.0" contype="1" conaffinity="1" type="mesh"/>
    </default>
    <default class="bb2_camera">
      <geom rgba="0.776 0.624 0.294 1.0"/>
    </default>
    <default class="wheel">
      <!-- Increased wheel friction for better traction -->
      <geom rgba="0.231 0.231 0.231 1.0" friction="2.0 0.005 0.005"/>
    </default>
    <default class="sick_lidar">
      <geom rgba="0.761 0.714 0.576 1.0"/>
    </default>
    <default class="dual_ur5_husky">
      <geom rgba="0.761 0.714 0.576 1.0"/>
    </default>
  </default>

  <asset>
    <!-- <hfield name="hfield" size="30 30 3 0.3" nrow="128" ncol="128" elevation="..."/> -->
    <texture type="skybox" builtin="gradient" rgb1="0.3 0.5 0.7" rgb2="0 0 0" width="512" height="3072"/>
    <texture builtin="checker" height="512" name="texplane" rgb1="0.2 0.3 0.4" rgb2="0.1 0.15 0.2" type="2d" width="512"/>
    <material name="floorplane" reflectance="0.5" texrepeat="1 1" texture="texplane" texuniform="true"/>
    <material name="plain" rgba="0.2 0.5 0.2 1"/>
    
    <mesh name="base_link" file="base_link.stl"/>
    <mesh name="wheel" file="wheel.stl"/>
    <mesh name="top_chassis" file="top_chassis.stl"/>
    <mesh name="bumper" file="bumper.stl"/>
    <mesh name="dual_arm_bulkhead" file="dual_arm_bulkhead.stl"/>
    <mesh name="flir-ptu-simple" file="flir-ptu-simple.stl"/>
    <mesh name="base" file="base.stl"/>
    <mesh name="shoulder" file="shoulder.stl"/>
    <mesh name="upperarm" file="upperarm.stl"/>
    <mesh name="forearm" file="forearm.stl"/>
    <mesh name="wrist1" file="wrist1.stl"/>
    <mesh name="wrist2" file="wrist2.stl"/>
    <mesh name="wrist3" file="wrist3.stl"/>
    <mesh name="sick-lms1xx" file="sick-lms1xx.stl"/>
    <mesh name="pointgrey_bumblebee2" file="pointgrey_bumblebee2.stl"/>
    <mesh name="robotiq_fts300" file="robotiq_fts300.stl"/>
    <mesh name="link_0" file="link_0.STL"/>
    <mesh name="link_1" file="link_1.STL"/>
    <mesh name="link_2" file="link_2.STL"/>
    <mesh name="link_3" file="link_3.STL"/>
    <mesh name="palm" file="palm.STL"/>
    <mesh name="collision_link_0" file="collision_link_0.STL"/>
    <mesh name="collision_link_1" file="collision_link_1.STL"/>
    <mesh name="collision_link_2" file="collision_link_2.STL"/>
    <mesh name="collision_link_3" file="collision_link_3.STL"/>
    <mesh name="collision_palm" file="collision_palm.STL"/>
    <mesh file="can.stl" name="can_mesh" scale="2.0 2.0 2.0"/>
    <mesh name="terrain_mesh" file="terrain.stl"/>
    <mesh name="wheel_cylinder" file="wheel_cylinder.stl"/>
  </asset>

  <worldbody>
    <camera name="fixed" pos="0 -2 2" zaxis="0 -1 1"/>
    <light directional="true" ambient="0.2 0.2 0.2" diffuse="0.8 0.8 0.8" specular="0.3 0.3 0.3" castshadow="false" pos="0 0 4" dir="0 0 -1" name="light0"/>
    <geom name="terrain" type="plane" size="30 30 0.1" material="plain" friction="1.5 0.005 0.005"/>

    <body name="robot0:base_link" pos="0 0 0.2">
      <freejoint name="robot0:root"/>
      <inertial diaginertia="1.2869 1.2236 0.9868" mass="70.1294" pos="-0.0036 0 0.0014" quat="0.7605 -0.0133 -0.0061 0.6491"/>
      
      <!-- Visual Geoms -->
      <geom type="mesh" contype="0" conaffinity="0" group="1" mesh="base_link"/>
      <geom type="mesh" contype="0" conaffinity="0" group="1" mesh="top_chassis" class="husky:orange"/>
      <geom pos="0.48 0 0.091" type="mesh" contype="0" conaffinity="0" group="1" mesh="bumper"/>
      <geom pos="-0.48 0 0.091" quat="0 0 0 1" type="mesh" contype="0" conaffinity="0" group="1" mesh="bumper"/>
      <geom pos="0 0 0.225" type="mesh" contype="0" conaffinity="0" group="1" mesh="dual_arm_bulkhead"/>
      <geom pos="0.465 0 0.14" quat="0.707107 0.707107 0 0" type="mesh" contype="0" conaffinity="0" group="1" mesh="sick-lms1xx" class="sick_lidar"/>
      
      <!-- Collision Geom for the chassis -->
      <geom name="base_link_collision" size="0.4937 0.28545 0.061875" pos="0 0 -0.06" type="box"/>

      <body name="front_left_wheel_link" pos="0.256 0.2854 0.03282">
        <inertial pos="0 0 0" quat="0.5 0.5 -0.5 0.5" mass="5.00" diaginertia="0.04411 0.02467 0.02467"/>
        <joint name="front_left_wheel" pos="0 0 0" axis="0 1 0" damping="0.5" armature="0.05"/>
        <geom type="mesh" contype="0" conaffinity="0" group="1" mesh="wheel" class="wheel"/>
        <!-- MODIFIED: Replaced mesh with capsule for collision -->
        <geom type="capsule" size="0.165 0.05" quat="0.707107 0.707107 0 0" class="wheel"/>
      </body>
      <body name="front_right_wheel_link" pos="0.256 -0.2854 0.03282">
        <inertial pos="0 0 0" quat="0.5 0.5 -0.5 0.5" mass="5.00" diaginertia="0.04411 0.02467 0.02467"/>
        <joint name="front_right_wheel" pos="0 0 0" axis="0 1 0" damping="0.5" armature="0.05"/>
        <geom type="mesh" contype="0" conaffinity="0" group="1" mesh="wheel" class="wheel"/>
        <!-- MODIFIED: Replaced mesh with capsule for collision -->
        <geom type="capsule" size="0.165 0.05" quat="0.707107 0.707107 0 0" class="wheel"/>
      </body>
      <body name="rear_left_wheel_link" pos="-0.256 0.2854 0.03282">
        <inertial pos="0 0 0" quat="0.5 0.5 -0.5 0.5" mass="5.00" diaginertia="0.04411 0.02467 0.02467"/>
        <joint name="rear_left_wheel" pos="0 0 0" axis="0 1 0" damping="0.5" armature="0.05"/>
        <geom type="mesh" contype="0" conaffinity="0" group="1" mesh="wheel" class="wheel"/>
        <!-- MODIFIED: Replaced mesh with capsule for collision -->
        <geom type="capsule" size="0.165 0.05" quat="0.707107 0.707107 0 0" class="wheel"/>
      </body>
      <body name="rear_right_wheel_link" pos="-0.256 -0.2854 0.03282">
        <inertial pos="0 0 0" quat="0.5 0.5 -0.5 0.5" mass="5.00" diaginertia="0.04411 0.02467 0.02467"/>
        <joint name="rear_right_wheel" pos="0 0 0" axis="0 1 0" damping="0.5" armature="0.05"/>
        <geom type="mesh" contype="0" conaffinity="0" group="1" mesh="wheel" class="wheel"/>
        <!-- MODIFIED: Replaced mesh with capsule for collision -->
        <geom type="capsule" size="0.165 0.05" quat="0.707107 0.707107 0 0" class="wheel"/>
      </body>
    </body>
  </worldbody>

  <tendon>
    <fixed name="forward">
      <joint joint="front_left_wheel" coef="1"/>
      <joint joint="rear_left_wheel" coef="1"/>
      <joint joint="front_right_wheel" coef="1"/>
      <joint joint="rear_right_wheel" coef="1"/>
    </fixed>
    <fixed name="turn">
      <joint joint="front_left_wheel" coef="-2"/>
      <joint joint="rear_left_wheel" coef="-2"/>
      <joint joint="front_right_wheel" coef="2"/>
      <joint joint="rear_right_wheel" coef="2"/>
    </fixed>
  </tendon>

  <actuator>
    <motor name="forward" tendon="forward" ctrlrange="-100.0 100.0" gear="1"/>
    <motor name="turn" tendon="turn" ctrlrange="-50.0 50.0" gear="1"/>
  </actuator>

  <sensor>
    <jointactuatorfrc name="front_left_force" joint="front_left_wheel"/>
    <jointactuatorfrc name="front_right_force" joint="front_right_wheel"/>
    <jointactuatorfrc name="rear_left_force" joint="rear_left_wheel"/>
    <jointactuatorfrc name="rear_right_force" joint="rear_right_wheel"/>
    <framepos name="base_position" objtype="body" objname="robot0:base_link"/>
    <frameangvel name="base_angular_velocity" objtype="body" objname="robot0:base_link"/>
  </sensor>
</mujoco>
